<?xml version="1.0"?>
<robot name="mesh_robot"
    xmlns:xacro="https://www.ros.org/wiki/xacro">
    <material name="blue">
        <color rgba="0 0 0.7 0.8" />
    </material>

    <link name="base_link">
        <visual>
            <origin xyz="0 0 0" rpy="0 0 0" />
            <geometry>
                <mesh filename="package://my_robot_description/mesh/waffle_base.stl" scale="0.01 0.01 0.01" />
            </geometry>
            <material name="blue"/>
        </visual>
    </link>

    <link name="left_wheel">
        <visual>
            <origin xyz="0 0 0" rpy="0 0 0" />
            <geometry>
                <mesh filename="package://my_robot_description/mesh/left_tire.stl" scale="0.01 0.01 0.01" />
            </geometry>
            <material name="grey">
                <color rgba="1 1 1 1" />
            </material>
        </visual>
    </link>

    <joint name="left_wheel_joint" type="continuous">
        <parent link="base_link" />
        <child link="left_wheel" />
        <origin xyz="0 0 0" rpy="0 0 0" />
        <axis xyz="0 1 0" />
    </joint>
</robot>